/usr/bin/python3: can't open file '/home/ubuntu/Bot.py': [Errno 2] No such file or directory
fatal: not a git repository (or any of the parent directories): .git
fatal: not a git repository (or any of the parent directories): .git
fatal: not a git repository (or any of the parent directories): .git
=====> Duties loaded <=====
=====> GROUP loaded <=====
<Response [422]>
Failed to send for üö®üö®üö® Hey Rui @8618881203470
üóëÔ∏è kitchen trash out duty is on you this week!

üóìÔ∏è Today is 2025-09-08 ‚Äî don‚Äôt forget! ‚è∞‚ú® to user 8618881203470 successfully.
[main 04b0836] [Bot] Update Duties
 1 file changed, 7 insertions(+)
To github.com:huminted/WhatsDutyBot.git
   cd33cec..04b0836  main -> main
=====> Duties loaded <=====
=====> GROUP loaded <=====
<Response [422]>
Failed to send for üö®üö®üö® Hey Viren @353899782720
‚ôªÔ∏è yard bins out duty is on you this week!

üóìÔ∏è Today is 2025-09-15 ‚Äî don‚Äôt forget! ‚è∞‚ú® to user 353899782720 successfully.
<Response [422]>
Failed to send for üö®üö®üö® Hey Rui @8618881203470
üóëÔ∏è kitchen trash out duty is on you this week!

üóìÔ∏è Today is 2025-09-15 ‚Äî don‚Äôt forget! ‚è∞‚ú® to user 8618881203470 successfully.
[main 0c94f43] [Bot] Update Duties
 1 file changed, 16 insertions(+)
To github.com:huminted/WhatsDutyBot.git
   04b0836..0c94f43  main -> main
=====> Duties loaded <=====
=====> GROUP loaded <=====
<Response [422]>
Failed to send for üö®üö®üö® Hey Dillen @917760360849
üóëÔ∏è kitchen trash out duty is on you this week!

üóìÔ∏è Today is 2025-09-22 ‚Äî don‚Äôt forget! ‚è∞‚ú® to user 917760360849 successfully.
[main d11defe] [Bot] Update Duties
 2 files changed, 8 insertions(+), 1 deletion(-)
To github.com:huminted/WhatsDutyBot.git
   3a7c582..d11defe  main -> main
=====> Duties loaded <=====
=====> GROUP loaded <=====
Traceback (most recent call last):
  File "/home/ubuntu/.local/lib/python3.10/site-packages/urllib3/connection.py", line 198, in _new_conn
    sock = connection.create_connection(
  File "/home/ubuntu/.local/lib/python3.10/site-packages/urllib3/util/connection.py", line 85, in create_connection
    raise err
  File "/home/ubuntu/.local/lib/python3.10/site-packages/urllib3/util/connection.py", line 73, in create_connection
    sock.connect(sa)
ConnectionRefusedError: [Errno 111] Connection refused

The above exception was the direct cause of the following exception:

Traceback (most recent call last):
  File "/home/ubuntu/.local/lib/python3.10/site-packages/urllib3/connectionpool.py", line 787, in urlopen
    response = self._make_request(
  File "/home/ubuntu/.local/lib/python3.10/site-packages/urllib3/connectionpool.py", line 493, in _make_request
    conn.request(
  File "/home/ubuntu/.local/lib/python3.10/site-packages/urllib3/connection.py", line 494, in request
    self.endheaders()
  File "/usr/lib/python3.10/http/client.py", line 1278, in endheaders
    self._send_output(message_body, encode_chunked=encode_chunked)
  File "/usr/lib/python3.10/http/client.py", line 1038, in _send_output
    self.send(msg)
  File "/usr/lib/python3.10/http/client.py", line 976, in send
    self.connect()
  File "/home/ubuntu/.local/lib/python3.10/site-packages/urllib3/connection.py", line 325, in connect
    self.sock = self._new_conn()
  File "/home/ubuntu/.local/lib/python3.10/site-packages/urllib3/connection.py", line 213, in _new_conn
    raise NewConnectionError(
urllib3.exceptions.NewConnectionError: <urllib3.connection.HTTPConnection object at 0x7fc97be862c0>: Failed to establish a new connection: [Errno 111] Connection refused

The above exception was the direct cause of the following exception:

Traceback (most recent call last):
  File "/home/ubuntu/.local/lib/python3.10/site-packages/requests/adapters.py", line 667, in send
    resp = conn.urlopen(
  File "/home/ubuntu/.local/lib/python3.10/site-packages/urllib3/connectionpool.py", line 841, in urlopen
    retries = retries.increment(
  File "/home/ubuntu/.local/lib/python3.10/site-packages/urllib3/util/retry.py", line 519, in increment
    raise MaxRetryError(_pool, url, reason) from reason  # type: ignore[arg-type]
urllib3.exceptions.MaxRetryError: HTTPConnectionPool(host='localhost', port=3001): Max retries exceeded with url: /api/sendText (Caused by NewConnectionError('<urllib3.connection.HTTPConnection object at 0x7fc97be862c0>: Failed to establish a new connection: [Errno 111] Connection refused'))

During handling of the above exception, another exception occurred:

Traceback (most recent call last):
  File "/home/ubuntu/WhatsDutyBot/Bot.py", line 88, in <module>
    notify_result = send(duty= duty, member=next_member,date=new_assign_date)
  File "/home/ubuntu/WhatsDutyBot/Bot.py", line 70, in send
    return send_notification(textwrap.dedent(content).strip(), "120363333596019764@g.us", member.phoneId)
  File "/home/ubuntu/WhatsDutyBot/Notifyer.py", line 28, in send_notification
    response = requests.post(url, json=notify_data, headers=headers)
  File "/home/ubuntu/.local/lib/python3.10/site-packages/requests/api.py", line 115, in post
    return request("post", url, data=data, json=json, **kwargs)
  File "/home/ubuntu/.local/lib/python3.10/site-packages/requests/api.py", line 59, in request
    return session.request(method=method, url=url, **kwargs)
  File "/home/ubuntu/.local/lib/python3.10/site-packages/requests/sessions.py", line 589, in request
    resp = self.send(prep, **send_kwargs)
  File "/home/ubuntu/.local/lib/python3.10/site-packages/requests/sessions.py", line 703, in send
    r = adapter.send(request, **kwargs)
  File "/home/ubuntu/.local/lib/python3.10/site-packages/requests/adapters.py", line 700, in send
    raise ConnectionError(e, request=request)
requests.exceptions.ConnectionError: HTTPConnectionPool(host='localhost', port=3001): Max retries exceeded with url: /api/sendText (Caused by NewConnectionError('<urllib3.connection.HTTPConnection object at 0x7fc97be862c0>: Failed to establish a new connection: [Errno 111] Connection refused'))
[main 49e1a2f] [Bot] Update Duties
 1 file changed, 63 insertions(+)
To github.com:huminted/WhatsDutyBot.git
   296d4d9..49e1a2f  main -> main
=====> Duties loaded <=====
=====> GROUP loaded <=====
Traceback (most recent call last):
  File "/home/ubuntu/.local/lib/python3.10/site-packages/urllib3/connection.py", line 198, in _new_conn
    sock = connection.create_connection(
  File "/home/ubuntu/.local/lib/python3.10/site-packages/urllib3/util/connection.py", line 85, in create_connection
    raise err
  File "/home/ubuntu/.local/lib/python3.10/site-packages/urllib3/util/connection.py", line 73, in create_connection
    sock.connect(sa)
ConnectionRefusedError: [Errno 111] Connection refused

The above exception was the direct cause of the following exception:

Traceback (most recent call last):
  File "/home/ubuntu/.local/lib/python3.10/site-packages/urllib3/connectionpool.py", line 787, in urlopen
    response = self._make_request(
  File "/home/ubuntu/.local/lib/python3.10/site-packages/urllib3/connectionpool.py", line 493, in _make_request
    conn.request(
  File "/home/ubuntu/.local/lib/python3.10/site-packages/urllib3/connection.py", line 494, in request
    self.endheaders()
  File "/usr/lib/python3.10/http/client.py", line 1278, in endheaders
    self._send_output(message_body, encode_chunked=encode_chunked)
  File "/usr/lib/python3.10/http/client.py", line 1038, in _send_output
    self.send(msg)
  File "/usr/lib/python3.10/http/client.py", line 976, in send
    self.connect()
  File "/home/ubuntu/.local/lib/python3.10/site-packages/urllib3/connection.py", line 325, in connect
    self.sock = self._new_conn()
  File "/home/ubuntu/.local/lib/python3.10/site-packages/urllib3/connection.py", line 213, in _new_conn
    raise NewConnectionError(
urllib3.exceptions.NewConnectionError: <urllib3.connection.HTTPConnection object at 0x7f699cf022c0>: Failed to establish a new connection: [Errno 111] Connection refused

The above exception was the direct cause of the following exception:

Traceback (most recent call last):
  File "/home/ubuntu/.local/lib/python3.10/site-packages/requests/adapters.py", line 667, in send
    resp = conn.urlopen(
  File "/home/ubuntu/.local/lib/python3.10/site-packages/urllib3/connectionpool.py", line 841, in urlopen
    retries = retries.increment(
  File "/home/ubuntu/.local/lib/python3.10/site-packages/urllib3/util/retry.py", line 519, in increment
    raise MaxRetryError(_pool, url, reason) from reason  # type: ignore[arg-type]
urllib3.exceptions.MaxRetryError: HTTPConnectionPool(host='localhost', port=3001): Max retries exceeded with url: /api/sendText (Caused by NewConnectionError('<urllib3.connection.HTTPConnection object at 0x7f699cf022c0>: Failed to establish a new connection: [Errno 111] Connection refused'))

During handling of the above exception, another exception occurred:

Traceback (most recent call last):
  File "/home/ubuntu/WhatsDutyBot/Bot.py", line 88, in <module>
    notify_result = send(duty= duty, member=next_member,date=new_assign_date)
  File "/home/ubuntu/WhatsDutyBot/Bot.py", line 70, in send
    return send_notification(textwrap.dedent(content).strip(), "120363333596019764@g.us", member.phoneId)
  File "/home/ubuntu/WhatsDutyBot/Notifyer.py", line 28, in send_notification
    response = requests.post(url, json=notify_data, headers=headers)
  File "/home/ubuntu/.local/lib/python3.10/site-packages/requests/api.py", line 115, in post
    return request("post", url, data=data, json=json, **kwargs)
  File "/home/ubuntu/.local/lib/python3.10/site-packages/requests/api.py", line 59, in request
    return session.request(method=method, url=url, **kwargs)
  File "/home/ubuntu/.local/lib/python3.10/site-packages/requests/sessions.py", line 589, in request
    resp = self.send(prep, **send_kwargs)
  File "/home/ubuntu/.local/lib/python3.10/site-packages/requests/sessions.py", line 703, in send
    r = adapter.send(request, **kwargs)
  File "/home/ubuntu/.local/lib/python3.10/site-packages/requests/adapters.py", line 700, in send
    raise ConnectionError(e, request=request)
requests.exceptions.ConnectionError: HTTPConnectionPool(host='localhost', port=3001): Max retries exceeded with url: /api/sendText (Caused by NewConnectionError('<urllib3.connection.HTTPConnection object at 0x7f699cf022c0>: Failed to establish a new connection: [Errno 111] Connection refused'))
[main 85eeba7] [Bot] Update Duties
 1 file changed, 67 insertions(+)
To github.com:huminted/WhatsDutyBot.git
   49e1a2f..85eeba7  main -> main
=====> Duties loaded <=====
=====> GROUP loaded <=====
Traceback (most recent call last):
  File "/home/ubuntu/.local/lib/python3.10/site-packages/urllib3/connection.py", line 198, in _new_conn
    sock = connection.create_connection(
  File "/home/ubuntu/.local/lib/python3.10/site-packages/urllib3/util/connection.py", line 85, in create_connection
    raise err
  File "/home/ubuntu/.local/lib/python3.10/site-packages/urllib3/util/connection.py", line 73, in create_connection
    sock.connect(sa)
ConnectionRefusedError: [Errno 111] Connection refused

The above exception was the direct cause of the following exception:

Traceback (most recent call last):
  File "/home/ubuntu/.local/lib/python3.10/site-packages/urllib3/connectionpool.py", line 787, in urlopen
    response = self._make_request(
  File "/home/ubuntu/.local/lib/python3.10/site-packages/urllib3/connectionpool.py", line 493, in _make_request
    conn.request(
  File "/home/ubuntu/.local/lib/python3.10/site-packages/urllib3/connection.py", line 494, in request
    self.endheaders()
  File "/usr/lib/python3.10/http/client.py", line 1278, in endheaders
    self._send_output(message_body, encode_chunked=encode_chunked)
  File "/usr/lib/python3.10/http/client.py", line 1038, in _send_output
    self.send(msg)
  File "/usr/lib/python3.10/http/client.py", line 976, in send
    self.connect()
  File "/home/ubuntu/.local/lib/python3.10/site-packages/urllib3/connection.py", line 325, in connect
    self.sock = self._new_conn()
  File "/home/ubuntu/.local/lib/python3.10/site-packages/urllib3/connection.py", line 213, in _new_conn
    raise NewConnectionError(
urllib3.exceptions.NewConnectionError: <urllib3.connection.HTTPConnection object at 0x7f3c5b9562c0>: Failed to establish a new connection: [Errno 111] Connection refused

The above exception was the direct cause of the following exception:

Traceback (most recent call last):
  File "/home/ubuntu/.local/lib/python3.10/site-packages/requests/adapters.py", line 667, in send
    resp = conn.urlopen(
  File "/home/ubuntu/.local/lib/python3.10/site-packages/urllib3/connectionpool.py", line 841, in urlopen
    retries = retries.increment(
  File "/home/ubuntu/.local/lib/python3.10/site-packages/urllib3/util/retry.py", line 519, in increment
    raise MaxRetryError(_pool, url, reason) from reason  # type: ignore[arg-type]
urllib3.exceptions.MaxRetryError: HTTPConnectionPool(host='localhost', port=3001): Max retries exceeded with url: /api/sendText (Caused by NewConnectionError('<urllib3.connection.HTTPConnection object at 0x7f3c5b9562c0>: Failed to establish a new connection: [Errno 111] Connection refused'))

During handling of the above exception, another exception occurred:

Traceback (most recent call last):
  File "/home/ubuntu/WhatsDutyBot/Bot.py", line 88, in <module>
    notify_result = send(duty= duty, member=next_member,date=new_assign_date)
  File "/home/ubuntu/WhatsDutyBot/Bot.py", line 70, in send
    return send_notification(textwrap.dedent(content).strip(), "120363333596019764@g.us", member.phoneId)
  File "/home/ubuntu/WhatsDutyBot/Notifyer.py", line 28, in send_notification
    response = requests.post(url, json=notify_data, headers=headers)
  File "/home/ubuntu/.local/lib/python3.10/site-packages/requests/api.py", line 115, in post
    return request("post", url, data=data, json=json, **kwargs)
  File "/home/ubuntu/.local/lib/python3.10/site-packages/requests/api.py", line 59, in request
    return session.request(method=method, url=url, **kwargs)
  File "/home/ubuntu/.local/lib/python3.10/site-packages/requests/sessions.py", line 589, in request
    resp = self.send(prep, **send_kwargs)
  File "/home/ubuntu/.local/lib/python3.10/site-packages/requests/sessions.py", line 703, in send
    r = adapter.send(request, **kwargs)
  File "/home/ubuntu/.local/lib/python3.10/site-packages/requests/adapters.py", line 700, in send
    raise ConnectionError(e, request=request)
requests.exceptions.ConnectionError: HTTPConnectionPool(host='localhost', port=3001): Max retries exceeded with url: /api/sendText (Caused by NewConnectionError('<urllib3.connection.HTTPConnection object at 0x7f3c5b9562c0>: Failed to establish a new connection: [Errno 111] Connection refused'))
